<?xml version="1.0" ?>
<!-- =================================================================================== -->
<!-- |    This document was autogenerated by xacro from CatModel2_v2.xacro             | -->
<!-- |    EDITING THIS FILE BY HAND IS NOT RECOMMENDED                                 | -->
<!-- =================================================================================== -->
<robot name="CatModel2_v2">
  <link name="base_link">
    <inertial>
      <origin rpy="0 0 0" xyz="0.0027732 -0.00068363 0.00099437"/>
      <mass value="0.29241"/>
      <inertia ixx="0.00035365" ixy="-9.4553E-08" ixz="3.37E-07" iyy="0.00014633" iyz="4.7012E-07" izz="0.00023997"/>
    </inertial>
    <visual>
      <origin rpy="0 0 0" xyz="0 0 0"/>
      <geometry>
        <mesh filename="package://CatModel2_v2_description/meshes/base_link.STL"/>
      </geometry>
      <material name="">
        <color rgba="0.752941176470588 0.752941176470588 0.752941176470588 1"/>
      </material>
    </visual>
  </link>
  <link name="BF_Link">
    <inertial>
      <origin rpy="0 0 0" xyz="0.12955 -8.3804E-05 -0.0013141"/>
      <mass value="3.1773"/>
      <inertia ixx="0.0048776" ixy="-5.0175E-06" ixz="-2.0519E-06" iyy="0.0043656" iyz="2.0409E-06" izz="0.0063374"/>
    </inertial>
    <visual>
      <origin rpy="0 0 0" xyz="0 0 0"/>
      <geometry>
        <mesh filename="package://CatModel2_v2_description/meshes/BF_Link.STL"/>
      </geometry>
      <material name="">
        <color rgba="0.752941176470588 0.752941176470588 0.752941176470588 1"/>
      </material>
    </visual>
    <collision>
      <origin rpy="0 0 0" xyz="0.13 0 0"/>
      <geometry>
        <box size="0.16 0.2 0.12"/>
      </geometry>
    </collision>
  </link>
  <joint name="bodyf_pitch_joint" type="revolute">
    <origin rpy="0 0 0" xyz="0 0 0"/>
    <parent link="base_link"/>
    <child link="BF_Link"/>
    <axis xyz="0 -1 0"/>
    <limit effort="23.7" lower="-0.75" upper="0.75" velocity="18"/>
  </joint>
  <link name="BB_Link">
    <inertial>
      <origin rpy="0 0 0" xyz="-0.155121047880281 -0.00203708989369605 -0.00355151701603064"/>
      <mass value="3.23275137200683"/>
      <inertia ixx="0.00514719625702028" ixy="1.12565222116179E-06" ixz="-1.95082644973759E-08" iyy="0.00417841726459602" iyz="-4.35796353082797E-06" izz="0.0068065106450055"/>
    </inertial>
    <visual>
      <origin rpy="0 0 0" xyz="0 0 0"/>
      <geometry>
        <mesh filename="package://CatModel2_v2_description/meshes/BB_Link.STL"/>
      </geometry>
      <material name="">
        <color rgba="0.752941176470588 0.752941176470588 0.752941176470588 1"/>
      </material>
    </visual>
    <collision>
      <origin rpy="0 0 0" xyz="-0.13 0 0"/>
      <geometry>
        <box size="0.18 0.2 0.12"/>
      </geometry>
    </collision>
  </link>
  <joint name="bodyb_yaw_joint" type="revolute">
    <origin rpy="0 0 0" xyz="0 0 0"/>
    <parent link="base_link"/>
    <child link="BB_Link"/>
    <axis xyz="0 0 1"/>
    <limit effort="23.7" lower="-0.75" upper="0.75" velocity="18"/>
  </joint>
  <link name="LF_hip">
    <inertial>
      <origin rpy="0 0 0" xyz="0.059149 0.00048753 5.429E-05"/>
      <mass value="0.64023"/>
      <inertia ixx="0.00043421" ixy="-7.3517E-08" ixz="-9.9092E-07" iyy="0.00072036" iyz="6.9084E-08" izz="0.00034295"/>
    </inertial>
    <visual>
      <origin rpy="0 0 0" xyz="0 0 0"/>
      <geometry>
        <mesh filename="package://CatModel2_v2_description/meshes/LF_hip.STL"/>
      </geometry>
      <material name="">
        <color rgba="0.752941176470588 0.752941176470588 0.752941176470588 1"/>
      </material>
    </visual>
  </link>
  <joint name="LF_HAA" type="revolute">
    <origin rpy="0 0 0" xyz="0.2106 0.05498 -0.00027501"/>
    <parent link="BF_Link"/>
    <child link="LF_hip"/>
    <axis xyz="1 0 0"/>
    <limit effort="23.7" lower="-0.785" upper="0.785" velocity="18"/>
  </joint>
  <link name="LF_thigh">
    <inertial>
      <origin rpy="0 0 0" xyz="-0.0032907 0.041874 -0.028566"/>
      <mass value="0.90246"/>
      <inertia ixx="0.0018817" ixy="-1.6738E-07" ixz="8.646E-05" iyy="0.0023903" iyz="-3.6595E-07" izz="0.00056291"/>
    </inertial>
    <visual>
      <origin rpy="0 0 0" xyz="0 0 0"/>
      <geometry>
        <mesh filename="package://CatModel2_v2_description/meshes/LF_thigh.STL"/>
      </geometry>
      <material name="">
        <color rgba="0.752941176470588 0.752941176470588 0.752941176470588 1"/>
      </material>
    </visual>
  </link>
  <joint name="LF_HFE" type="revolute">
    <origin rpy="0 0 0" xyz="0.065399 0.02005 0"/>
    <parent link="LF_hip"/>
    <child link="LF_thigh"/>
    <axis xyz="0 1 0"/>
    <limit effort="23.7" lower="-1.05" upper="3.14" velocity="18"/>
  </joint>
  <link name="LF_calf">
    <inertial>
      <origin rpy="0 0 0" xyz="0 -3.1641E-15 -0.052658"/>
      <mass value="0.14476"/>
      <inertia ixx="0.00035039" ixy="1.2339E-20" ixz="3.6484E-19" iyy="0.00037167" iyz="2.4131E-18" izz="2.3499E-05"/>
    </inertial>
    <visual>
      <origin rpy="0 0 0" xyz="0 0 0"/>
      <geometry>
        <mesh filename="package://CatModel2_v2_description/meshes/LF_calf.STL"/>
      </geometry>
      <material name="">
        <color rgba="0.101960784313725 0.101960784313725 0.101960784313725 1"/>
      </material>
    </visual>
    <collision>
      <origin rpy="0 1.5707963267948966 0" xyz="0.0 0 -0.068"/>
      <geometry>
        <box size="0.18 0.02 0.03"/>
      </geometry>
    </collision>
  </link>
  <joint name="LF_KFE" type="revolute">
    <origin rpy="0 0 0" xyz="0 0.0617 -0.22"/>
    <parent link="LF_thigh"/>
    <child link="LF_calf"/>
    <axis xyz="0 1 0"/>
    <limit effort="23.7" lower="-2.70" upper="-0.92" velocity="18"/>
  </joint>
  <link name="LF_FOOT">
    <visual>
      <origin rpy="0 0 0" xyz="0 0 0"/>
      <geometry>
        <sphere radius="0.01"/>
      </geometry>
      <material name="">
        <color rgba="0.752941176470588 0.752941176470588 0.752941176470588 1"/>
      </material>
    </visual>
    <collision>
      <origin rpy="0 0 0" xyz="0 0 0"/>
      <geometry>
        <sphere radius="0.02"/>
      </geometry>
    </collision>
    <inertial>
      <mass value="0.06"/>
      <inertia ixx="9.600000000000001e-06" ixy="0.0" ixz="0.0" iyy="9.600000000000001e-06" iyz="0.0" izz="9.600000000000001e-06"/>
    </inertial>
  </link>
  <joint name="LF_foot_fixed" type="fixed">
    <origin rpy="0 0 0" xyz="-0.001 0 -0.18"/>
    <parent link="LF_calf"/>
    <child link="LF_FOOT"/>
  </joint>
  <link name="RF_hip">
    <inertial>
      <origin rpy="0 0 0" xyz="0.0591490581019896 -0.000487525970476965 -5.42903367248861E-05"/>
      <mass value="0.640225051482545"/>
      <inertia ixx="0.000434212543234904" ixy="7.35174336445234E-08" ixz="9.90921151292404E-07" iyy="0.000720360810738487" iyz="6.90839528752722E-08" izz="0.000342952443359203"/>
    </inertial>
    <visual>
      <origin rpy="0 0 0" xyz="0 0 0"/>
      <geometry>
        <mesh filename="package://CatModel2_v2_description/meshes/RF_hip.STL"/>
      </geometry>
      <material name="">
        <color rgba="0.752941176470588 0.752941176470588 0.752941176470588 1"/>
      </material>
    </visual>
  </link>
  <joint name="RF_HAA" type="revolute">
    <origin rpy="0 0 0" xyz="0.2106 -0.05502 -0.00027501"/>
    <parent link="BF_Link"/>
    <child link="RF_hip"/>
    <axis xyz="1 0 0"/>
    <limit effort="23.7" lower="-0.785" upper="0.785" velocity="18"/>
  </joint>
  <link name="RF_thigh">
    <inertial>
      <origin rpy="0 0 0" xyz="-0.00317848322957781 -0.0418855537001225 -0.0284736552743077"/>
      <mass value="0.902455135679806"/>
      <inertia ixx="0.0018815550203863" ixy="-1.67383947337767E-07" ixz="8.24129006656969E-05" iyy="0.00239029186292115" iyz="-5.15964742906776E-07" izz="0.000563095477798709"/>
    </inertial>
    <visual>
      <origin rpy="0 0 0" xyz="0 0 0"/>
      <geometry>
        <mesh filename="package://CatModel2_v2_description/meshes/RF_thigh.STL"/>
      </geometry>
      <material name="">
        <color rgba="0.752941176470588 0.752941176470588 0.752941176470588 1"/>
      </material>
    </visual>
  </link>
  <joint name="RF_HFE" type="revolute">
    <origin rpy="0 0 0" xyz="0.065399 -0.02005 0"/>
    <parent link="RF_hip"/>
    <child link="RF_thigh"/>
    <axis xyz="0 1 0"/>
    <limit effort="23.7" lower="-1.05" upper="3.14" velocity="18"/>
  </joint>
  <link name="RF_calf">
    <inertial>
      <origin rpy="0 0 0" xyz="6.66133814775094E-16 -6.22765727875674E-15 -0.0526579498337946"/>
      <mass value="0.144759009545624"/>
      <inertia ixx="0.000350393411843135" ixy="2.0050448906824E-20" ixz="4.21763248200571E-19" iyy="0.000371665464074352" iyz="2.01157508959523E-18" izz="2.34988672673909E-05"/>
    </inertial>
    <visual>
      <origin rpy="0 0 0" xyz="0 0 0"/>
      <geometry>
        <mesh filename="package://CatModel2_v2_description/meshes/RF_calf.STL"/>
      </geometry>
      <material name="">
        <color rgba="0.101960784313725 0.101960784313725 0.101960784313725 1"/>
      </material>
    </visual>
    <collision>
      <origin rpy="0 1.5707963267948966 0" xyz="0.0 0 -0.068"/>
      <geometry>
        <box size="0.18 0.02 0.03"/>
      </geometry>
    </collision>
  </link>
  <joint name="RF_KFE" type="revolute">
    <origin rpy="0 0 0" xyz="0 -0.0617 -0.22"/>
    <parent link="RF_thigh"/>
    <child link="RF_calf"/>
    <axis xyz="0 1 0"/>
    <limit effort="23.7" lower="-2.70" upper="-0.92" velocity="18"/>
  </joint>
  <link name="RF_FOOT">
    <visual>
      <origin rpy="0 0 0" xyz="0 0 0"/>
      <geometry>
        <sphere radius="0.01"/>
      </geometry>
      <material name="">
        <color rgba="0.752941176470588 0.752941176470588 0.752941176470588 1"/>
      </material>
    </visual>
    <collision>
      <origin rpy="0 0 0" xyz="0 0 0"/>
      <geometry>
        <sphere radius="0.02"/>
      </geometry>
    </collision>
    <inertial>
      <mass value="0.06"/>
      <inertia ixx="9.600000000000001e-06" ixy="0.0" ixz="0.0" iyy="9.600000000000001e-06" iyz="0.0" izz="9.600000000000001e-06"/>
    </inertial>
  </link>
  <joint name="RF_foot_fixed" type="fixed">
    <origin rpy="0 0 0" xyz="-0.001 0 -0.18"/>
    <parent link="RF_calf"/>
    <child link="RF_FOOT"/>
  </joint>
  <link name="LH_hip">
    <inertial>
      <origin rpy="0 0 0" xyz="-0.0591490581019898 0.000487525970477076 -5.42903367247473E-05"/>
      <mass value="0.64022505148254"/>
      <inertia ixx="0.0004342125432349" ixy="7.35174336447589E-08" ixz="-9.90921151293637E-07" iyy="0.000720360810738482" iyz="-6.90839528781593E-08" izz="0.000342952443359201"/>
    </inertial>
    <visual>
      <origin rpy="0 0 0" xyz="0 0 0"/>
      <geometry>
        <mesh filename="package://CatModel2_v2_description/meshes/LH_hip.STL"/>
      </geometry>
      <material name="">
        <color rgba="0.752941176470588 0.752941176470588 0.752941176470588 1"/>
      </material>
    </visual>
  </link>
  <joint name="LH_HAA" type="revolute">
    <origin rpy="0 0 0" xyz="-0.2306 0.05498 -0.00027501"/>
    <parent link="BB_Link"/>
    <child link="LH_hip"/>
    <axis xyz="1 0 0"/>
    <limit effort="23.7" lower="-0.785" upper="0.785" velocity="18"/>
  </joint>
  <link name="LH_thigh">
    <inertial>
      <origin rpy="0 0 0" xyz="-0.00326537744186078 0.0418738032783046 -0.0284484128464969"/>
      <mass value="0.90245513578387"/>
      <inertia ixx="0.00188150914405838" ixy="-1.67383947515894E-07" ixz="8.60940761571269E-05" iyy="0.0023902918629742" iyz="-3.65953825948848E-07" izz="0.000563141354181181"/>
    </inertial>
    <visual>
      <origin rpy="0 0 0" xyz="0 0 0"/>
      <geometry>
        <mesh filename="package://CatModel2_v2_description/meshes/LH_thigh.STL"/>
      </geometry>
      <material name="">
        <color rgba="0.752941176470588 0.752941176470588 0.752941176470588 1"/>
      </material>
    </visual>
  </link>
  <joint name="LH_HFE" type="revolute">
    <origin rpy="0 0 0" xyz="-0.065399 0.02005 0"/>
    <parent link="LH_hip"/>
    <child link="LH_thigh"/>
    <axis xyz="0 1 0"/>
    <limit effort="23.7" lower="-1.05" upper="3.14" velocity="18"/>
  </joint>
  <link name="LH_calf">
    <inertial>
      <origin rpy="0 0 0" xyz="1.11022302462516E-16 8.88178419700125E-16 -0.0526579498337902"/>
      <mass value="0.144759009545624"/>
      <inertia ixx="0.000350393411843134" ixy="2.56586676497705E-20" ixz="6.47243391334494E-21" iyy="0.000371665464074352" iyz="-2.65071817579223E-18" izz="2.34988672673909E-05"/>
    </inertial>
    <visual>
      <origin rpy="0 0 0" xyz="0 0 0"/>
      <geometry>
        <mesh filename="package://CatModel2_v2_description/meshes/LH_calf.STL"/>
      </geometry>
      <material name="">
        <color rgba="0.101960784313725 0.101960784313725 0.101960784313725 1"/>
      </material>
    </visual>
    <collision>
      <origin rpy="0 1.5707963267948966 0" xyz="0.0 0 -0.068"/>
      <geometry>
        <box size="0.18 0.02 0.03"/>
      </geometry>
    </collision>
  </link>
  <joint name="LH_KFE" type="revolute">
    <origin rpy="0 0 0" xyz="0 0.0617 -0.22"/>
    <parent link="LH_thigh"/>
    <child link="LH_calf"/>
    <axis xyz="0 1 0"/>
    <limit effort="23.7" lower="-2.70" upper="-0.92" velocity="18"/>
  </joint>
  <link name="LH_FOOT">
    <visual>
      <origin rpy="0 0 0" xyz="0 0 0"/>
      <geometry>
        <sphere radius="0.01"/>
      </geometry>
      <material name="">
        <color rgba="0.752941176470588 0.752941176470588 0.752941176470588 1"/>
      </material>
    </visual>
    <collision>
      <origin rpy="0 0 0" xyz="0 0 0"/>
      <geometry>
        <sphere radius="0.02"/>
      </geometry>
    </collision>
    <inertial>
      <mass value="0.06"/>
      <inertia ixx="9.600000000000001e-06" ixy="0.0" ixz="0.0" iyy="9.600000000000001e-06" iyz="0.0" izz="9.600000000000001e-06"/>
    </inertial>
  </link>
  <joint name="LH_foot_fixed" type="fixed">
    <origin rpy="0 0 0" xyz="-0.001 0 -0.18"/>
    <parent link="LH_calf"/>
    <child link="LH_FOOT"/>
  </joint>
  <link name="RH_hip">
    <inertial>
      <origin rpy="0 0 0" xyz="-0.0589998656454742 -0.000506527943530136 -1.58979394321024E-05"/>
      <mass value="0.642366646261419"/>
      <inertia ixx="0.000434440011866329" ixy="-7.3517433644117E-08" ixz="9.90921151292079E-07" iyy="0.000720364692882" iyz="-6.90839528753E-08" izz="0.000343179911990631"/>
    </inertial>
    <visual>
      <origin rpy="0 0 0" xyz="0 0 0"/>
      <geometry>
        <mesh filename="package://CatModel2_v2_description/meshes/RH_hip.STL"/>
      </geometry>
      <material name="">
        <color rgba="0.752941176470588 0.752941176470588 0.752941176470588 1"/>
      </material>
    </visual>
  </link>
  <joint name="RH_HAA" type="revolute">
    <origin rpy="0 0 0" xyz="-0.2306 -0.05502 -0.00027501"/>
    <parent link="BB_Link"/>
    <child link="RH_hip"/>
    <axis xyz="1 0 0"/>
    <limit effort="23.7" lower="-0.785" upper="0.785" velocity="18"/>
  </joint>
  <link name="RH_thigh">
    <inertial>
      <origin rpy="0 0 0" xyz="-0.00317232321632233 -0.0418855537024003 -0.028448412846502"/>
      <mass value="0.902455135783871"/>
      <inertia ixx="0.00188150914405838" ixy="-1.67383947516652E-07" ixz="8.23311898038298E-05" iyy="0.0023902918629742" iyz="-5.15964720207777E-07" izz="0.000563141354181178"/>
    </inertial>
    <visual>
      <origin rpy="0 0 0" xyz="0 0 0"/>
      <geometry>
        <mesh filename="package://CatModel2_v2_description/meshes/RH_thigh.STL"/>
      </geometry>
      <material name="">
        <color rgba="0.752941176470588 0.752941176470588 0.752941176470588 1"/>
      </material>
    </visual>
  </link>
  <joint name="RH_HFE" type="revolute">
    <origin rpy="0 0 0" xyz="-0.065399 -0.02005 0"/>
    <parent link="RH_hip"/>
    <child link="RH_thigh"/>
    <axis xyz="0 1 0"/>
    <limit effort="23.7" lower="-1.05" upper="3.14" velocity="18"/>
  </joint>
  <link name="RH_calf">
    <inertial>
      <origin rpy="0 0 0" xyz="-4.9960036108132E-16 9.54097911787244E-16 -0.0526579498337933"/>
      <mass value="0.144759009545625"/>
      <inertia ixx="0.000350393411843135" ixy="2.1155328601958E-21" ixz="3.60949306388038E-21" iyy="0.000371665464074352" iyz="-2.27593210856691E-18" izz="2.34988672673909E-05"/>
    </inertial>
    <visual>
      <origin rpy="0 0 0" xyz="0 0 0"/>
      <geometry>
        <mesh filename="package://CatModel2_v2_description/meshes/RH_calf.STL"/>
      </geometry>
      <material name="">
        <color rgba="0.101960784313725 0.101960784313725 0.101960784313725 1"/>
      </material>
    </visual>
    <collision>
      <origin rpy="0 1.5707963267948966 0" xyz="0.0 0 -0.068"/>
      <geometry>
        <box size="0.18 0.02 0.03"/>
      </geometry>
    </collision>
  </link>
  <joint name="RH_KFE" type="revolute">
    <origin rpy="0 0 0" xyz="0 -0.0617 -0.22"/>
    <parent link="RH_thigh"/>
    <child link="RH_calf"/>
    <axis xyz="0 1 0"/>
    <limit effort="23.7" lower="-2.70" upper="-0.92" velocity="18"/>
  </joint>
  <link name="RH_FOOT">
    <visual>
      <origin rpy="0 0 0" xyz="0 0 0"/>
      <geometry>
        <sphere radius="0.01"/>
      </geometry>
      <material name="">
        <color rgba="0.752941176470588 0.752941176470588 0.752941176470588 1"/>
      </material>
    </visual>
    <collision>
      <origin rpy="0 0 0" xyz="0 0 0"/>
      <geometry>
        <sphere radius="0.02"/>
      </geometry>
    </collision>
    <inertial>
      <mass value="0.06"/>
      <inertia ixx="9.600000000000001e-06" ixy="0.0" ixz="0.0" iyy="9.600000000000001e-06" iyz="0.0" izz="9.600000000000001e-06"/>
    </inertial>
  </link>
  <joint name="RH_foot_fixed" type="fixed">
    <origin rpy="0 0 0" xyz="-0.001 0 -0.18"/>
    <parent link="RH_calf"/>
    <child link="RH_FOOT"/>
  </joint>
  <!-- Imu is fixed to the base link -->
  <joint name="base_imu_joint" type="fixed">
    <origin rpy="0. 0. 0." xyz=" 0.05 0. 0.08"/>
    <parent link="base_link"/>
    <child link="base_imu"/>
  </joint>
  <!-- Imu link -->
  <link name="base_imu">
    <inertial>
      <mass value="0.01"/>
      <origin rpy="0 0 0" xyz="0 0 0"/>
      <inertia ixx="0.000001" ixy="0" ixz="0" iyy="0.000001" iyz="0" izz="0.000001"/>
    </inertial>
    <visual>
      <origin rpy="0 0 0" xyz="0 0 0"/>
      <geometry>
        <box size="0.015 0.015 0.004"/>
      </geometry>
    </visual>
    <material name="orange">
      <color rgba="255 108 10 255"/>
    </material>
  </link>
</robot>
